<?xml version="1.0"?>

<robot name = "proto3" xmlns:xacro="http://www.ros.org/wiki/xacro">
    <xacro:include filename="$(find proto3_description)/urdf/proto3_gazebo.xacro" />
    <xacro:include filename="$(find proto3_description)/urdf/proto3_ros2_control.xacro"/>
    
    <xacro:property name = "PI" value = "3.1416"/>
    <link name = "world"/>

    <joint name="world_to_l0" type="fixed">
        <parent link="world"/>
        <child link="L0"/>
        <origin xyz="0 0 0" rpy="0 0 0"/>
    </joint>

    <!-- Camera link with adjusted position -->
    <link name="camera">
    <visual>
        <origin xyz="-0.0471 -0.0859 -0.0397" rpy="0 0 0"/>
        <geometry>
        <mesh filename="package://proto3_description/meshes/camera.STL" scale="0.001 0.001 0.001"/>
        </geometry>
        <material name="Mild Steel">
        <color rgba="0.79216 0.81961 0.93333 1"/>
        </material>
    </visual>
    <collision>
        <origin xyz="-0.0471 -0.0859 -0.0397" rpy="0 0 0"/>
        <geometry>
        <mesh filename="package://proto3_description/meshes/camera.STL" scale="0.001 0.001 0.001"/>
        </geometry>
    </collision>
    <inertial>
        <mass value="0.1"/>
        <inertia ixx="0.001" ixy="0" ixz="0" iyy="0.001" iyz="0" izz="0.001"/>
    </inertial>
    </link>

    <joint name="camera_joint" type="fixed">
    <parent link="world"/>  <!-- Change this to the appropriate parent link -->
    <child link="camera"/>
    <!-- Adjust these values to position the camera correctly on your robot -->
    <origin xyz="1 0.5 1" rpy="${-PI/4} 0 ${PI/2}"/>
    </joint>

    <!-- Camera optical frame -->
    <link name="camera_optical_frame">
    <inertial>
        <mass value="0.001"/>
        <inertia ixx="0.0001" ixy="0" ixz="0" iyy="0.0001" iyz="0" izz="0.0001"/>
    </inertial>
    </link>

    <!-- Joint from camera to camera optical frame -->
    <joint name="camera_optical_joint" type="fixed">
    <parent link="camera"/>
    <child link="camera_optical_frame"/>
    <!-- This rotation aligns the optical frame correctly so Z is the optical axis -->
    <!-- Based on your screenshot, you want the green axis (Y in standard ROS frames) to be the optical axis -->
    <origin xyz="0 0 0" rpy="${-PI/2} 0 ${-PI/2}"/>
    </joint>

    
    <link name="L0">
        <inertial>
        <origin xyz="0 0.0079001 0.16566" rpy="0 0 0" />
        <mass value="4.9171" />
        
        <inertia
            ixx="0.047585"
            ixy="3.753E-06"
            ixz="-3.3031E-06"
            iyy="0.052491"
            iyz="-3.8946E-05"
            izz="0.073326" />
        </inertial>

        <visual>
            <origin xyz="0 0 0" rpy="0 0 0" />
            <geometry>
                <mesh filename="package://proto3_description/meshes/L0.STL" />
            </geometry>
            <material name="Mild Steel">
                <color rgba="0.79216 0.81961 0.93333 1" />
            </material>
        </visual>
        
        <collision>
            <origin xyz="0 0 0" rpy="0 0 0" />
            <geometry>
                <mesh filename="package://proto3_description/meshes/L0.STL" />
            </geometry>
        </collision>
    </link>

    <joint name="J01" type="revolute">
        <origin xyz="0 0 0.252" rpy="${PI/2} 0 ${PI}" />
        <parent link="L0" />
        <child link="L1" />
        <axis xyz="0 1 0" />
    
        <limit 
            lower="${-PI}"
            upper="${PI}"
            effort="238"
            velocity="3.1415" />
    
    </joint>

    <link name="L1">
        <inertial>
            <origin xyz="0.0060396 0.17595 0" rpy="0 0 0" />
            <mass value="8.9408" />
            <inertia
                ixx="0.047293"
                ixy="-6.6381E-06"
                ixz="1.5788E-05"
                iyy="0.044741"
                iyz="-3.0638E-08"
                izz="0.034665" />
        </inertial>
        
        <visual>
            <origin xyz="0 0 0" rpy="0 0 0" />
        
            <geometry>
                <mesh filename="package://proto3_description/meshes/L1.STL" />
            </geometry>
        
            <material name="Mild Steel">
                <color rgba="0.79216 0.81961 0.93333 1" />
            </material>
        
        </visual>
    
        <collision>
        
            <origin xyz="0 0 0" rpy="0 0 0" />
            
            <geometry>
                <mesh filename="package://proto3_description/meshes/L1.STL" />
            </geometry>
        
        </collision>
  
    </link>

    <joint name="J12" type="revolute">
        
        <origin xyz="0 0.214 0" rpy="3.1416 0 3.1416" />
        
        <parent link="L1" />
        <child link="L2" />
        
        <axis xyz="-1 0 0" />
        <limit
            lower="${-1*PI/2}"
            upper="${PI/2}"
            effort="1145"
            velocity="3.1417" />
        
    </joint>

    <link name="L2">
        <inertial>
        <origin xyz="0.014107 0.21491 0.00023161" rpy="0 0 0" />
        
        <mass value="26.303" />
        
        <inertia
            ixx="0.15254"
            ixy="1.2724E-05"
            ixz="2.5354E-05"
            iyy="0.092042"
            iyz="-7.5375E-06"
            izz="0.14678" />
        </inertial>

        <visual>
        <origin xyz="0 0 0" rpy="0 0 0" />
        
        <geometry>
            <mesh filename="package://proto3_description/meshes/L2.STL" />
        </geometry>
        
        <material name="Mild Steel">
            <color rgba="0.79216 0.81961 0.93333 1" />
        </material>
        </visual>
        
        <collision>
        <origin xyz="0 0 0" rpy="0 0 0" />
        
        <geometry>
            <mesh filename="package://proto3_description/meshes/L2.STL" />
        </geometry>
        
        </collision>
    </link>

    <joint name="J23" type="revolute">

        <origin xyz="0 0.45 0" rpy="-1.5708 0 0" />
        <parent link="L2" />
        <child link="L3" />
        <axis xyz="1 0 0" />
        
        <limit
        lower="${-1* PI/2}"
        upper="${PI/2}"
        effort="459"
        velocity="3.14" />

    </joint>

    <link name="L3">
        <inertial>
        <origin xyz="0.00083915 -0.055853 0.15446" rpy="0 0 0" />
        <mass value="4.3153" />
        
        <inertia
            ixx="0.025988"
            ixy="6.1299E-07"
            ixz="-8.1067E-18"
            iyy="0.02556"
            iyz="0.0039698"
            izz="0.0097655" />
        </inertial>
        
        <visual>
            <origin xyz="0 0 0" rpy="0 0 0" />
            
            <geometry>
                <mesh filename="package://proto3_description/meshes/L3.STL" />
            </geometry>
            
            <material name="Mild Steel">
                <color rgba="0.79216 0.81961 0.93333 1" />
            </material>
        </visual>
        
        <collision>
            <origin xyz="0 0 0" rpy="0 0 0" />
            <geometry>
                <mesh filename="package://proto3_description/meshes/L3.STL" />
            </geometry>
        </collision>
    </link>

    <joint name="J34" type="revolute">
        <origin xyz="0 0 0.215" rpy="0 -1.5708 0" />
        <parent link="L3" />
        <child link="L4" />
        <axis xyz="0 1 0" />

        <limit
        lower="${-1*PI}"
        upper="${PI}"
        effort="127"
        velocity="3.14" />


    </joint>

    <link name="L4">
        <inertial>
        
        <origin xyz="0 0.20715 0" rpy="0 0 0" />
        <mass value="3.7365" />
        
        <inertia
            ixx="0.044096"
            ixy="-2.0295E-06"
            ixz="-1.114E-06"
            iyy="0.012077"
            iyz="-5.9426E-06"
            izz="0.047271" />
        </inertial>
        
        <visual>
        <origin xyz="0 0 0" rpy="0 0 0" />
        
        <geometry>
            <mesh filename="package://proto3_description/meshes/L4.STL" />
        </geometry>
        
        <material name="Mild Steel">
            <color rgba="0.79216 0.81961 0.93333 1" />
        </material>
        
        </visual>

        <collision>
        <origin xyz="0 0 0" rpy="0 0 0" />
        <geometry>
            <mesh filename="package://proto3_description/meshes/L4.STL" />
        </geometry>
        </collision>
    </link>

    <joint name="J45" type="revolute">
        <origin xyz="0 0.45 0" rpy="0 0 0" />
        <parent link="L4" />
        <child link="L5" />
        <axis xyz="0 0 1" />
        <limit 
            lower="-${PI/2}" 
            upper="${PI/2}" 
            effort="120" 
            velocity="3.14" />
    </joint>  

    <link name="L5">
        <inertial>
        <origin xyz="0 0.0086302 0" rpy="0 0 0" />
        <mass value="0.48612" />

        <inertia
            ixx="0.00045949"
            ixy="-2.7389E-09"
            ixz="-5.3792E-10"
            iyy="0.00053278"
            iyz="1.2289E-07"
            izz="0.00042861" />
        </inertial>

        <visual>
            <origin xyz="0 0 0" rpy="0 0 0" />
            <geometry>
                <mesh filename="package://proto3_description/meshes/L5.STL" />
            </geometry>
            
            <material name="Mild Steel">
                <color rgba="0.79216 0.81961 0.93333 1" />
            </material>
        </visual>

        <collision>
            <origin xyz="0 0 0" rpy="0 0 0" />
            <geometry>
                <mesh filename="package://proto3_description/meshes/L5.STL" />
            </geometry>
        </collision>
    </link>

    <joint name="J56" type="revolute">
        <origin xyz="0 0.0071 0" rpy="0 0 0" />
        <parent link="L5" />
        <child link="L6" />
        <axis xyz="0 -1 0" />
        <limit
            lower="-${PI}"
            upper="${PI}"
            effort="120"
            velocity="3.14" />
    </joint>

    <link name="L6">
        <inertial>
        <origin xyz="0 0.060013 0" rpy="0 0 0" />
        <mass value="0.44036" />
        
        <inertia
            ixx="0.00015681"
            ixy="5.0039E-20"
            ixz="2.2321E-21"
            iyy="0.00026506"
            iyz="-3.0357E-08"
            izz="0.00015747" />
        </inertial>
        
        <visual>
        <origin xyz="0 0 0" rpy="0 0 0" />
        <geometry>
            <mesh filename="package://proto3_description/meshes/L6.STL" />
        </geometry>
        <material name="Mild Steel">
            <color rgba="0.79216 0.81961 0.93333 1" />
        </material>
        </visual>
        
        <collision>
        <origin xyz="0 0 0" rpy="0 0 0" />
        <geometry>
            <mesh filename="package://proto3_description/meshes/L6.STL" />
        </geometry>
        </collision>
    </link>

</robot>